<?xml version="1.0" encoding="utf-8"?>
<!-- This URDF was automatically created by SolidWorks to URDF Exporter! Originally created by Stephen Brawner (brawner@gmail.com) 
     Commit Version: 1.6.0-1-g15f4949  Build Version: 1.6.7594.29634
     For more information, please see http://wiki.ros.org/sw_urdf_exporter -->
<robot
  name="ahman_robot_arm_description">
  <link
    name="base_link">
    <inertial>
      <origin
        xyz="-0.0621296478374961 -0.000197013108224509 0.0262458650036686"
        rpy="0 0 0" />
      <mass
        value="1.57548174222026" />
      <inertia
        ixx="0.00228921323959943"
        ixy="-1.89613899616038E-07"
        ixz="-0.000914717756802455"
        iyy="0.0111783484880427"
        iyz="-9.28094744189398E-08"
        izz="0.0126774912847455" />
    </inertial>
    <visual>
      <origin
        xyz="0 0 0"
        rpy="0 0 0" />
      <geometry>
        <mesh
          filename="package://ahman_robot_arm_description/meshes/base_link.STL" />
      </geometry>
      <material
        name="">
        <color
          rgba="1 1 1 1" />
      </material>
    </visual>
    <collision>
      <origin
        xyz="0 0 0"
        rpy="0 0 0" />
      <geometry>
        <mesh
          filename="package://ahman_robot_arm_description/meshes/base_link.STL" />
      </geometry>
    </collision>
  </link>
  <link
    name="shoulder_link">
    <inertial>
      <origin
        xyz="0.000282603902537829 1.44505199131673E-05 0.0112110401977242"
        rpy="0 0 0" />
      <mass
        value="0.12558913401628" />
      <inertia
        ixx="0.00012714430786896"
        ixy="-9.26769562100987E-08"
        ixz="5.79420738002533E-15"
        iyy="0.000128437631153157"
        iyz="1.78900511672797E-07"
        izz="0.000252635335314004" />
    </inertial>
    <visual>
      <origin
        xyz="0 0 0"
        rpy="0 0 0" />
      <geometry>
        <mesh
          filename="package://ahman_robot_arm_description/meshes/shoulder_link.STL" />
      </geometry>
      <material
        name="">
        <color
          rgba="0.894117647058823 0.913725490196078 0.929411764705882 1" />
      </material>
    </visual>
    <collision>
      <origin
        xyz="0 0 0"
        rpy="0 0 0" />
      <geometry>
        <mesh
          filename="package://ahman_robot_arm_description/meshes/shoulder_link.STL" />
      </geometry>
    </collision>
  </link>
  <joint
    name="shoulder_joint"
    type="revolute">
    <origin
      xyz="0 0 0.0905"
      rpy="0 0 0" />
    <parent
      link="base_link" />
    <child
      link="shoulder_link" />
    <axis
      xyz="0 0 1" />
    <limit
      lower="-2.618"
      upper="2.618"
      effort="0"
      velocity="0" />
  </joint>
  <link
    name="bicep_link">
    <inertial>
      <origin
        xyz="-1.07646010161222E-09 0.00254632887372314 0.0671287671446354"
        rpy="0 0 0" />
      <mass
        value="0.0228631437999219" />
      <inertia
        ixx="2.39073149613632E-05"
        ixy="2.32866187605332E-13"
        ixz="1.28584632604654E-13"
        iyy="1.31818096379652E-05"
        iyz="9.63935414958932E-14"
        izz="1.29556718766971E-05" />
    </inertial>
    <visual>
      <origin
        xyz="0 0 0"
        rpy="0 0 0" />
      <geometry>
        <mesh
          filename="package://ahman_robot_arm_description/meshes/bicep_link.STL" />
      </geometry>
      <material
        name="">
        <color
          rgba="0.666666666666667 0.698039215686274 0.768627450980392 1" />
      </material>
    </visual>
    <collision>
      <origin
        xyz="0 0 0"
        rpy="0 0 0" />
      <geometry>
        <mesh
          filename="package://ahman_robot_arm_description/meshes/bicep_link.STL" />
      </geometry>
    </collision>
  </link>
  <joint
    name="bicep_joint"
    type="revolute">
    <origin
      xyz="0.011637 0.00030135 0.0232"
      rpy="0 0 0" />
    <parent
      link="shoulder_link" />
    <child
      link="bicep_link" />
    <axis
      xyz="0 -1 0" />
    <limit
      lower="-2.618"
      upper="2.618"
      effort="0"
      velocity="0" />
  </joint>
  <link
    name="elbow_link">
    <inertial>
      <origin
        xyz="-0.00185354151846942 -0.000935407374379416 0.0102619236268282"
        rpy="0 0 0" />
      <mass
        value="0.0548714607838969" />
      <inertia
        ixx="1.35412600787717E-05"
        ixy="1.68915939744945E-07"
        ixz="-2.05466079914059E-08"
        iyy="8.872576856175E-06"
        iyz="-8.96949891636742E-08"
        izz="8.07530038782251E-06" />
    </inertial>
    <visual>
      <origin
        xyz="0 0 0"
        rpy="0 0 0" />
      <geometry>
        <mesh
          filename="package://ahman_robot_arm_description/meshes/elbow_link.STL" />
      </geometry>
      <material
        name="">
        <color
          rgba="0.666666666666667 0.698039215686274 0.768627450980392 1" />
      </material>
    </visual>
    <collision>
      <origin
        xyz="0 0 0"
        rpy="0 0 0" />
      <geometry>
        <mesh
          filename="package://ahman_robot_arm_description/meshes/elbow_link.STL" />
      </geometry>
    </collision>
  </link>
  <joint
    name="elbow_joint"
    type="revolute">
    <origin
      xyz="0 0 0.135"
      rpy="0 0 0" />
    <parent
      link="bicep_link" />
    <child
      link="elbow_link" />
    <axis
      xyz="0 1 0" />
    <limit
      lower="-2.618"
      upper="2.618"
      effort="0"
      velocity="0" />
  </joint>
  <link
    name="wrist_link">
    <inertial>
      <origin
        xyz="-0.0110556086395542 0.000211230238021221 0.033198352764828"
        rpy="0 0 0" />
      <mass
        value="0.0215560015176652" />
      <inertia
        ixx="4.98645899014325E-06"
        ixy="-1.53565858408592E-08"
        ixz="-5.67433972481255E-10"
        iyy="3.56530485474667E-06"
        iyz="-6.51916422698559E-08"
        izz="2.64942430962807E-06" />
    </inertial>
    <visual>
      <origin
        xyz="0 0 0"
        rpy="0 0 0" />
      <geometry>
        <mesh
          filename="package://ahman_robot_arm_description/meshes/wrist_link.STL" />
      </geometry>
      <material
        name="">
        <color
          rgba="0.666666666666667 0.698039215686274 0.768627450980392 1" />
      </material>
    </visual>
    <collision>
      <origin
        xyz="0 0 0"
        rpy="0 0 0" />
      <geometry>
        <mesh
          filename="package://ahman_robot_arm_description/meshes/wrist_link.STL" />
      </geometry>
    </collision>
  </link>
  <joint
    name="wrist_joint"
    type="revolute">
    <origin
      xyz="-0.0030616 -0.0095697 0.078229"
      rpy="0 0 0" />
    <parent
      link="elbow_link" />
    <child
      link="wrist_link" />
    <axis
      xyz="0 0 -1" />
    <limit
      lower="-2.618"
      upper="2.618"
      effort="0"
      velocity="0" />
  </joint>
  <link
    name="gripper_power_link">
    <inertial>
      <origin
        xyz="-0.00299189792266995 4.87283713379583E-10 -6.82270240304206E-10"
        rpy="0 0 0" />
      <mass
        value="0.00250405869863455" />
      <inertia
        ixx="9.57060201376116E-08"
        ixy="-6.75092632909777E-15"
        ixz="9.45230874454392E-15"
        iyy="6.35955949295357E-08"
        iyz="-2.22068247712848E-15"
        izz="6.35955964527919E-08" />
    </inertial>
    <visual>
      <origin
        xyz="0 0 0"
        rpy="0 0 0" />
      <geometry>
        <mesh
          filename="package://ahman_robot_arm_description/meshes/gripper_power_link.STL" />
      </geometry>
      <material
        name="">
        <color
          rgba="0.317647058823529 0.247058823529412 0.207843137254902 1" />
      </material>
    </visual>
    <collision>
      <origin
        xyz="0 0 0"
        rpy="0 0 0" />
      <geometry>
        <mesh
          filename="package://ahman_robot_arm_description/meshes/gripper_power_link.STL" />
      </geometry>
    </collision>
  </link>
  <joint
    name="gripper_power_joint"
    type="revolute">
    <origin
      xyz="0.0013154 0.0075085 0.02978"
      rpy="0 0 -0.008706" />
    <parent
      link="wrist_link" />
    <child
      link="gripper_power_link" />
    <axis
      xyz="1 0 0" />
    <limit
      lower="-2.618"
      upper="2.618"
      effort="0"
      velocity="0" />
  </joint>
  <link
    name="right_gear_link">
    <inertial>
      <origin
        xyz="-0.00193086606490488 0.00665199997650162 0"
        rpy="0 0 0" />
      <mass
        value="0.00265775053226582" />
      <inertia
        ixx="4.32773768952486E-07"
        ixy="8.6957361894637E-23"
        ixz="-1.04864559343279E-23"
        iyy="8.34336695921308E-08"
        iyz="-3.51728516490222E-22"
        izz="3.57982565471374E-07" />
    </inertial>
    <visual>
      <origin
        xyz="0 0 0"
        rpy="0 0 0" />
      <geometry>
        <mesh
          filename="package://ahman_robot_arm_description/meshes/right_gear_link.STL" />
      </geometry>
      <material
        name="">
        <color
          rgba="0.894117647058823 0.913725490196078 0.929411764705882 1" />
      </material>
    </visual>
    <collision>
      <origin
        xyz="0 0 0"
        rpy="0 0 0" />
      <geometry>
        <mesh
          filename="package://ahman_robot_arm_description/meshes/right_gear_link.STL" />
      </geometry>
    </collision>
  </link>
  <joint
    name="right_gear_joint"
    type="continuous">
    <origin
      xyz="0.00425 0.0059803 0.019825"
      rpy="0 0 0" />
    <parent
      link="gripper_power_link" />
    <child
      link="right_gear_link" />
    <axis
      xyz="1 0 0" />
  </joint>
  <link
    name="right_finger_link">
    <inertial>
      <origin
        xyz="-2.08166817117217E-17 -0.00495816296253876 0.0222920054918524"
        rpy="0 0 0" />
      <mass
        value="0.00296891525111355" />
      <inertia
        ixx="9.24608677627611E-07"
        ixy="-2.48154183765908E-23"
        ixz="4.20214162821715E-22"
        iyy="8.87593583276421E-07"
        iyz="1.18086134887375E-07"
        izz="4.61243075404796E-08" />
    </inertial>
    <visual>
      <origin
        xyz="0 0 0"
        rpy="0 0 0" />
      <geometry>
        <mesh
          filename="package://ahman_robot_arm_description/meshes/right_finger_link.STL" />
      </geometry>
      <material
        name="">
        <color
          rgba="0.666666666666667 0.698039215686274 0.768627450980392 1" />
      </material>
    </visual>
    <collision>
      <origin
        xyz="0 0 0"
        rpy="0 0 0" />
      <geometry>
        <mesh
          filename="package://ahman_robot_arm_description/meshes/right_finger_link.STL" />
      </geometry>
    </collision>
  </link>
  <joint
    name="right_finger_joint"
    type="continuous">
    <origin
      xyz="-0.00550000000000002 0.0309999999999999 0"
      rpy="0 0 0" />
    <parent
      link="right_gear_link" />
    <child
      link="right_finger_link" />
    <axis
      xyz="1 0 0" />
  </joint>
  <link
    name="left_gear_link">
    <inertial>
      <origin
        xyz="-0.00206477938876969 -0.00712705692013643 0.000470998597776329"
        rpy="0 0 0" />
      <mass
        value="0.00248537947426595" />
      <inertia
        ixx="4.0136467834394E-07"
        ixy="-1.57681304267921E-23"
        ixz="-2.31373731218934E-23"
        iyy="6.99862270448919E-08"
        iyz="-7.20770201979305E-09"
        izz="3.39762360823067E-07" />
    </inertial>
    <visual>
      <origin
        xyz="0 0 0"
        rpy="0 0 0" />
      <geometry>
        <mesh
          filename="package://ahman_robot_arm_description/meshes/left_gear_link.STL" />
      </geometry>
      <material
        name="">
        <color
          rgba="0.894117647058823 0.913725490196078 0.929411764705882 1" />
      </material>
    </visual>
    <collision>
      <origin
        xyz="0 0 0"
        rpy="0 0 0" />
      <geometry>
        <mesh
          filename="package://ahman_robot_arm_description/meshes/left_gear_link.STL" />
      </geometry>
    </collision>
  </link>
  <joint
    name="left_gear_joint"
    type="continuous">
    <origin
      xyz="0.00424999999999987 -0.0210196797413557 0.0198250616521198"
      rpy="0 0 0" />
    <parent
      link="gripper_power_link" />
    <child
      link="left_gear_link" />
    <axis
      xyz="1 0 0" />
  </joint>
  <link
    name="left_finger_link">
    <inertial>
      <origin
        xyz="-9.71445146547012E-17 0.00495816296253726 0.022292005491854"
        rpy="0 0 0" />
      <mass
        value="0.00296891525111356" />
      <inertia
        ixx="9.24608677627618E-07"
        ixy="9.0989867380833E-24"
        ixz="8.21040874406667E-23"
        iyy="8.87593583276427E-07"
        iyz="-1.18086134887379E-07"
        izz="4.61243075404806E-08" />
    </inertial>
    <visual>
      <origin
        xyz="0 0 0"
        rpy="0 0 0" />
      <geometry>
        <mesh
          filename="package://ahman_robot_arm_description/meshes/left_finger_link.STL" />
      </geometry>
      <material
        name="">
        <color
          rgba="0.666666666666667 0.698039215686274 0.768627450980392 1" />
      </material>
    </visual>
    <collision>
      <origin
        xyz="0 0 0"
        rpy="0 0 0" />
      <geometry>
        <mesh
          filename="package://ahman_robot_arm_description/meshes/left_finger_link.STL" />
      </geometry>
    </collision>
  </link>
  <joint
    name="left_finger_joint"
    type="continuous">
    <origin
      xyz="-0.00549999999999974 -0.0309999999999988 0"
      rpy="0 0 0" />
    <parent
      link="left_gear_link" />
    <child
      link="left_finger_link" />
    <axis
      xyz="1 0 0" />
  </joint>
  <link
    name="right_knuckle_link">
    <inertial>
      <origin
        xyz="-2.77555756156289E-17 0.0173787993335969 0"
        rpy="0 0 0" />
      <mass
        value="0.000933047329406333" />
      <inertia
        ixx="1.16126442123931E-07"
        ixy="2.25245158207311E-23"
        ixz="-3.90387807891087E-25"
        iyy="4.80779497694863E-09"
        iyz="1.15442274314176E-21"
        izz="1.17374058453712E-07" />
    </inertial>
    <visual>
      <origin
        xyz="0 0 0"
        rpy="0 0 0" />
      <geometry>
        <mesh
          filename="package://ahman_robot_arm_description/meshes/right_knuckle_link.STL" />
      </geometry>
      <material
        name="">
        <color
          rgba="0.898039215686275 0.92156862745098 0.929411764705882 1" />
      </material>
    </visual>
    <collision>
      <origin
        xyz="0 0 0"
        rpy="0 0 0" />
      <geometry>
        <mesh
          filename="package://ahman_robot_arm_description/meshes/right_knuckle_link.STL" />
      </geometry>
    </collision>
  </link>
  <joint
    name="right_knuckle_joint"
    type="continuous">
    <origin
      xyz="4.57059260836959E-05 0.00524980104083161 0.0699998597650424"
      rpy="0 0 -0.00870600054853568" />
    <parent
      link="wrist_link" />
    <child
      link="right_knuckle_link" />
    <axis
      xyz="1 0 0" />
  </joint>
  <link
    name="left_knuckle_link">
    <inertial>
      <origin
        xyz="-3.46944695195361E-17 -0.0173787993335969 -3.33066907387547E-16"
        rpy="0 0 0" />
      <mass
        value="0.000933047329406329" />
      <inertia
        ixx="1.16126442123931E-07"
        ixy="-2.33613899560875E-24"
        ixz="7.93899145342149E-25"
        iyy="4.80779497694861E-09"
        iyz="1.42199126179906E-22"
        izz="1.17374058453712E-07" />
    </inertial>
    <visual>
      <origin
        xyz="0 0 0"
        rpy="0 0 0" />
      <geometry>
        <mesh
          filename="package://ahman_robot_arm_description/meshes/left_knuckle_link.STL" />
      </geometry>
      <material
        name="">
        <color
          rgba="0.898039215686275 0.92156862745098 0.929411764705882 1" />
      </material>
    </visual>
    <collision>
      <origin
        xyz="0 0 0"
        rpy="0 0 0" />
      <geometry>
        <mesh
          filename="package://ahman_robot_arm_description/meshes/left_knuckle_link.STL" />
      </geometry>
    </collision>
  </link>
  <joint
    name="left_knuckle_joint"
    type="continuous">
    <origin
      xyz="-4.5705924913951E-05 -0.00524980104084261 0.0699998597650426"
      rpy="0 0 -0.00870600054853568" />
    <parent
      link="wrist_link" />
    <child
      link="left_knuckle_link" />
    <axis
      xyz="1 0 0" />
  </joint>
</robot>